<?xml version="1.0" ?>
<!-- ======================================================================= -->
<!-- | This document was autogenerated by xacro from lbr_iiwa.urdf.xacro   | -->
<!-- | Original xacro: https://github.com/rtkg/lbr_iiwa/archive/master.zip | -->
<!-- | EDITING THIS FILE BY HAND IS NOT RECOMMENDED                        | -->
<!-- | Changes (kohlhoff):                                                 | -->
<!-- |   * Removed gazebo tags.                                            | -->
<!-- |   * Removed unused materials.                                       | -->
<!-- |   * Made mesh paths relative.                                       | -->
<!-- |   * Removed material fields from collision segments.                | -->
<!-- |   * Removed the self_collision_checking segment.                    | -->
<!-- |   * Removed transmission segments, since they didn't match the      | -->
<!-- |     convention, will have to added back later.                      | -->
<!-- ======================================================================= -->
<!--LICENSE:                                                                 -->
<!--Copyright (c) 2015, Robert Krug & Todor Stoyanov, AASS Research Center,  -->
<!--Orebro University, Sweden                                                -->
<!--All rights reserved.                                                     -->
<!--                                                                         -->
<!--Redistribution and use in source and binary forms, with or without       -->
<!--modification, are permitted provided that the following conditions are   -->
<!--met:                                                                     -->
<!--                                                                         -->
<!--1. Redistributions of source code must retain the above copyright notice,-->
<!--   this list of conditions and the following disclaimer.                 -->
<!--                                                                         -->
<!--2. Redistributions in binary form must reproduce the above copyright     -->
<!--   notice, this list of conditions and the following disclaimer in the   -->
<!--   documentation and/or other materials provided with the distribution.  -->
<!--                                                                         -->
<!--THIS SOFTWARE IS PROVIDED BY THE COPYRIGHT HOLDERS AND CONTRIBUTORS "AS  -->
<!--IS" AND ANY EXPRESS OR IMPLIED WARRANTIES, INCLUDING, BUT NOT LIMITED TO,-->
<!--THE IMPLIED WARRANTIES OF MERCHANTABILITY AND FITNESS FOR A PARTICULAR   -->
<!--PURPOSE ARE DISCLAIMED. IN NO EVENT SHALL THE COPYRIGHT HOLDER OR        -->
<!--CONTRIBUTORS BE LIABLE FOR ANY DIRECT, INDIRECT, INCIDENTAL, SPECIAL,    -->
<!--EXEMPLARY, OR CONSEQUENTIAL DAMAGES (INCLUDING, BUT NOT LIMITED TO,      -->
<!--PROCUREMENT OF SUBSTITUTE GOODS OR SERVICES; LOSS OF USE, DATA, OR       -->
<!--PROFITS; OR BUSINESS INTERRUPTION) HOWEVER CAUSED AND ON ANY THEORY OF   -->
<!--LIABILITY, WHETHER IN CONTRACT, STRICT LIABILITY, OR TORT (INCLUDING     -->
<!--NEGLIGENCE OR OTHERWISE) ARISING IN ANY WAY OUT OF THE USE OF THIS       -->
<!--SOFTWARE, EVEN IF ADVISED OF THE POSSIBILITY OF SUCH DAMAGE.             -->
<robot name="lbr_iiwa" xmlns:xacro="http://www.ros.org/wiki/xacro">
  <!-- Import Rviz colors -->
  <material name="Grey">
    <color rgba="0.2 0.2 0.2 1.0"/>
  </material>
  <material name="Orange">
    <color rgba="1.0 0.423529411765 0.0392156862745 1.0"/>
  </material>
  <material name="Blue">
    <color rgba="0.5 0.7 1.0 1.0"/>      
  </material>

  <link name="base_link">
    <inertial>
      <origin rpy="0 0 0" xyz="0 0 0.05"/>
      <mass value="1.2"/>
      <inertia ixx="1" ixy="0" ixz="0" iyy="1" iyz="0" izz="1"/>
    </inertial>
    <visual>
      <origin rpy="0 0 0" xyz="0 0 0"/>
      <geometry>
        <mesh filename="meshes/WSG50_110.stl"/>
      </geometry>
    </visual>
    <collision>
      <origin rpy="0 0 0" xyz="0 0 0"/>
      <geometry>
        <mesh filename="meshes/WSG50_110.stl"/>
      </geometry>
    </collision>
  </link>
  <!-- left finger-->
  <joint name="base_link_gripper_left" type="prismatic">
    <parent link="base_link"/>
    <child link="gripper_left"/>
    <origin rpy="0 0 0" xyz="-0.055 0 0.0"/>
    <axis xyz="1 0 0"/>
    <limit lower="0.0" upper="0.055" effort="1" velocity="1"/>
  </joint>
  <link name="gripper_left">
  	<contact>
      <lateral_friction value="5.0"/>
      <rolling_friction value="1.0"/>
    </contact>
    <inertial>
      <origin rpy="0 0 0" xyz="0 0 0.03"/>
      <mass value="0.2"/>
      <inertia ixx=".1" ixy="0" ixz="0" iyy=".1" iyz="0" izz=".1"/>
    </inertial>
    <visual>
      <origin rpy="0 0 0" xyz="0 0 0"/>
      <geometry>
        <mesh filename="meshes/GUIDE_WSG50_110.stl" scale="0.001 0.001 0.001"/>
      </geometry>
    </visual>
    <visual>
      <origin rpy="0 0 0" xyz="0 0 0.023"/>
      <geometry>
        <mesh filename="meshes/WSG-FMF.stl" scale="0.001 0.001 0.001"/>
      </geometry>
    </visual>
    <collision>
      <origin rpy="0 0 0" xyz="0 0 0.0"/>
      <geometry>
          <mesh filename="meshes/GUIDE_WSG50_110.stl" scale="0.001 0.001 0.001"/>
      </geometry>
    </collision>
    <collision>
      <origin rpy="0 0 0" xyz="0 0 0.023"/>
      <geometry>
          <mesh filename="meshes/WSG-FMF.stl" scale="0.001 0.001 0.001"/>
      </geometry>
    </collision>
  </link>
  <joint name="gripper_finger_left" type="fixed">
    <parent link="gripper_left"/>
    <child link="finger_left"/>
    <origin rpy="0 0 0" xyz="0 0 0.145"/>
  </joint>
  <link name="finger_left">
    <contact>
      <lateral_friction value="5.0"/>
      <rolling_friction value="1.0"/>
    </contact>
    <inertial>
      <origin rpy="0 0 0" xyz="0 0 0.042"/>
      <mass value="0.2"/>
      <inertia ixx=".1" ixy="0" ixz="0" iyy=".1" iyz="0" izz=".1"/>
    </inertial>
    <visual>
      <origin rpy="0 0 4.71239" xyz="0 0 0.0"/>
      <geometry>
        <mesh filename="meshes/l_gripper_tip_scaled.stl"/>
      </geometry>
    </visual>
    <collision>
      <origin rpy="0 0 0" xyz="0 0 0.042"/>
      <geometry>
        <box size="0.02 0.02 0.15"/>
      </geometry>
    </collision>
  </link>
  <!-- right finger-->
  <joint name="base_link_gripper_right" type="prismatic">
    <parent link="base_link"/>
    <child link="gripper_right"/>
    <axis xyz="1 0 0"/>
    <limit lower="0" upper="0.055" effort="1" velocity="1"/>
    <origin rpy="0 0 3.14159" xyz="0.055 0 0"/>
  </joint>
  <link name="gripper_right">
  	<contact>
      <lateral_friction value="5.0"/>
      <rolling_friction value="1.0"/>
    </contact>
    <inertial>
      <origin rpy="0 0 0" xyz="0 0 0.03"/>
      <mass value="0.2"/>
      <inertia ixx=".1" ixy="0" ixz="0" iyy=".1" iyz="0" izz=".1"/>
    </inertial>
    <visual>
      <origin rpy="0 0 0" xyz="0 0 0"/>
      <geometry>
        <mesh filename="meshes/GUIDE_WSG50_110.stl" scale="0.001 0.001 0.001"/>
      </geometry>
    </visual>
    <visual>
      <origin rpy="0 0 0" xyz="0 0 0.023"/>
      <geometry>
        <mesh filename="meshes/WSG-FMF.stl" scale="0.001 0.001 0.001"/>
      </geometry>
    </visual>
    <collision>
      <origin rpy="0 0 0" xyz="0.0 0 0.0"/>
      <geometry>
          <mesh filename="meshes/GUIDE_WSG50_110.stl" scale="0.001 0.001 0.001"/>
      </geometry>
    </collision>
    <collision>
      <origin rpy="0 0 0" xyz="0 0 0.023"/>
      <geometry>
          <mesh filename="meshes/WSG-FMF.stl" scale="0.001 0.001 0.001"/>
      </geometry>
    </collision>
  </link>
  <joint name="gripper_finger_right" type="fixed">
    <parent link="gripper_right"/>
    <child link="finger_right"/>
    <origin rpy="0 0 0" xyz="0 0 0.145"/>
  </joint>
  <link name="finger_right">
  	<contact>
      <lateral_friction value="5.0"/>
      <rolling_friction value="1.0"/>
    </contact>
    <inertial>
      <origin rpy="0 0 0" xyz="0 0 0.042"/>
      <mass value="0.2"/>
      <inertia ixx=".1" ixy="0" ixz="0" iyy=".1" iyz="0" izz=".1"/>
    </inertial>
    <visual>
      <origin rpy="0 0 4.71239" xyz="0 0 0.0"/>
      <geometry>
        <mesh filename="meshes/l_gripper_tip_scaled.stl"/>
      </geometry>
    </visual>
    <collision>
      <origin rpy="0 0 0" xyz="0 0 0.042"/>
      <geometry>
        <box size="0.02 0.02 0.15"/>
      </geometry>
    </collision>
  </link>
</robot>

